 
 -------------- celery@942b093f8a8a v5.0.5 (singularity)
--- ***** ----- 
-- ******* ---- Linux-5.4.0-1019-gcp-x86_64-with-glibc2.27 2021-02-24 09:57:50
- *** --- * --- 
- ** ---------- [config]
- ** ---------- .> app:         CVEMonitor:0x7f8307e8cdf0
- ** ---------- .> transport:   sqla+sqlite:///CVEMonitor_worker.db
- ** ---------- .> results:     disabled://
- *** --- * --- .> concurrency: 4 (prefork)
-- ******* ---- .> task events: OFF (enable -E to monitor tasks in this worker)
--- ***** ----- 
 -------------- [queues]
                .> celery           exchange=celery(direct) key=celery
                

[tasks]
  . task.feishu
  . task.mail_to

[2021-02-24 09:57:52,459: INFO/MainProcess] Connected to sqla+sqlite:///CVEMonitor_worker.db
[2021-02-24 09:57:52,950: INFO/MainProcess] celery@942b093f8a8a ready.
[2021-02-24 09:57:53,182: INFO/MainProcess] Received task: task.feishu[b95e4ff4-1e12-4566-b1b6-6ea8f2d85ec2]  
[2021-02-24 09:57:53,413: INFO/MainProcess] Received task: task.feishu[286cefe5-41ad-48a8-9deb-8cfb12f61042]  
[2021-02-24 09:57:53,582: INFO/MainProcess] Received task: task.feishu[e63c18c7-16d4-435b-9076-d9ab346f1d69]  
[2021-02-24 09:57:53,884: INFO/MainProcess] Received task: task.feishu[2ac02731-a36b-46c7-8ad4-c0bbef28e1a4]  
[2021-02-24 09:57:54,027: INFO/MainProcess] Received task: task.feishu[5fe6dcf3-8047-424e-aedb-8548a9d8ded9]  
[2021-02-24 09:57:54,653: INFO/ForkPoolWorker-2] Task task.feishu[b95e4ff4-1e12-4566-b1b6-6ea8f2d85ec2] succeeded in 1.4648664359992836s: None
[2021-02-24 09:57:54,764: INFO/MainProcess] Received task: task.feishu[cf196597-f900-4286-a0e8-17b85201e98a]  
[2021-02-24 09:57:54,758: INFO/ForkPoolWorker-4] Task task.feishu[286cefe5-41ad-48a8-9deb-8cfb12f61042] succeeded in 1.3083898609984317s: None
[2021-02-24 09:57:54,885: INFO/ForkPoolWorker-1] Task task.feishu[e63c18c7-16d4-435b-9076-d9ab346f1d69] succeeded in 1.2969344160010223s: None
[2021-02-24 09:57:55,009: INFO/MainProcess] Received task: task.feishu[4b9aacd2-cca2-4df0-bf7c-f8cfb3f5457c]  
[2021-02-24 09:57:55,153: INFO/MainProcess] Received task: task.feishu[b6976f0d-8c5f-4c1f-ba52-7741871e228d]  
[2021-02-24 09:57:55,190: INFO/ForkPoolWorker-2] Task task.feishu[5fe6dcf3-8047-424e-aedb-8548a9d8ded9] succeeded in 0.5178830529985134s: None
[2021-02-24 09:57:55,217: INFO/ForkPoolWorker-3] Task task.feishu[2ac02731-a36b-46c7-8ad4-c0bbef28e1a4] succeeded in 1.3248988499981351s: None
[2021-02-24 09:57:55,265: INFO/MainProcess] Received task: task.feishu[eaecbfc5-8558-4403-b308-8264bfa03b43]  
[2021-02-24 09:57:55,471: INFO/MainProcess] Received task: task.feishu[455945d0-b194-4018-b79a-9b4069ba5e52]  
[2021-02-24 09:57:55,535: INFO/ForkPoolWorker-4] Task task.feishu[cf196597-f900-4286-a0e8-17b85201e98a] succeeded in 0.7595057380021899s: None
[2021-02-24 09:57:55,649: INFO/ForkPoolWorker-1] Task task.feishu[4b9aacd2-cca2-4df0-bf7c-f8cfb3f5457c] succeeded in 0.6023405749947415s: None
[2021-02-24 09:57:55,660: INFO/MainProcess] Received task: task.feishu[524d7f78-63de-45b6-a1fb-7a1b65243dfe]  
[2021-02-24 09:57:55,787: INFO/ForkPoolWorker-2] Task task.feishu[b6976f0d-8c5f-4c1f-ba52-7741871e228d] succeeded in 0.5850881830047001s: None
[2021-02-24 09:57:55,860: INFO/MainProcess] Received task: task.feishu[c55c672d-8edf-4f44-97d5-0fe886d6f03f]  
[2021-02-24 09:57:56,022: INFO/MainProcess] Received task: task.feishu[9b84ea0c-5ae5-4adc-856f-67a075f5baf1]  
[2021-02-24 09:57:56,065: INFO/ForkPoolWorker-4] Task task.feishu[455945d0-b194-4018-b79a-9b4069ba5e52] succeeded in 0.5101847690020804s: None
[2021-02-24 09:57:56,165: INFO/MainProcess] Received task: task.feishu[4c8cbdf9-765a-44f4-be6b-1f89bfabcd56]  
[2021-02-24 09:57:56,271: INFO/ForkPoolWorker-1] Task task.feishu[524d7f78-63de-45b6-a1fb-7a1b65243dfe] succeeded in 0.6043523730040761s: None
[2021-02-24 09:57:56,387: INFO/ForkPoolWorker-2] Task task.feishu[c55c672d-8edf-4f44-97d5-0fe886d6f03f] succeeded in 0.5087430990024586s: None
[2021-02-24 09:57:56,445: INFO/MainProcess] Received task: task.feishu[b9de2d20-ce66-4ff5-bfc9-613fe8914127]  
[2021-02-24 09:57:56,555: INFO/MainProcess] Received task: task.feishu[4816f861-6207-4028-bf32-a77b65f7ba80]  
[2021-02-24 09:57:56,597: INFO/ForkPoolWorker-4] Task task.feishu[9b84ea0c-5ae5-4adc-856f-67a075f5baf1] succeeded in 0.5259922800032655s: None
[2021-02-24 09:57:56,619: INFO/ForkPoolWorker-3] Task task.feishu[eaecbfc5-8558-4403-b308-8264bfa03b43] succeeded in 1.3447782439980074s: None
[2021-02-24 09:57:56,745: INFO/MainProcess] Received task: task.mail_to[f6f8090b-36e3-416f-85af-5b290896f440]  
[2021-02-24 09:57:56,758: INFO/ForkPoolWorker-3] [=][33m收到邮件发送任务  发件人: [ak47__98k@163.com]  主机: [smtp.163.com:25]  目标: [['ak47__98k@163.com', 'yaoyq@lianlianpay.com']]  内容: [70][0m
[2021-02-24 09:57:56,857: INFO/MainProcess] Received task: task.mail_to[a7614315-48f4-479a-b621-3758247b22a3]  
[2021-02-24 09:57:56,863: INFO/ForkPoolWorker-1] Task task.feishu[4c8cbdf9-765a-44f4-be6b-1f89bfabcd56] succeeded in 0.5820582000014838s: None
[2021-02-24 09:57:56,872: INFO/ForkPoolWorker-1] [=][33m收到邮件发送任务  发件人: [ak47__98k@163.com]  主机: [smtp.163.com:25]  目标: [['ak47__98k@163.com', 'yaoyq@lianlianpay.com']]  内容: [70][0m
[2021-02-24 09:57:56,949: INFO/ForkPoolWorker-2] Task task.feishu[b9de2d20-ce66-4ff5-bfc9-613fe8914127] succeeded in 0.5009101210016524s: None
[2021-02-24 09:57:56,988: INFO/MainProcess] Received task: task.mail_to[c7439ea7-0780-4801-9ef6-c376c1de57b5]  
[2021-02-24 09:57:56,991: INFO/ForkPoolWorker-2] [=][33m收到邮件发送任务  发件人: [ak47__98k@163.com]  主机: [smtp.163.com:25]  目标: [['ak47__98k@163.com', 'yaoyq@lianlianpay.com']]  内容: [70][0m
[2021-02-24 09:57:57,064: INFO/MainProcess] Received task: task.mail_to[a6ea014a-a69d-4f09-9886-2687268a737f]  
[2021-02-24 09:57:57,076: INFO/ForkPoolWorker-4] Task task.feishu[4816f861-6207-4028-bf32-a77b65f7ba80] succeeded in 0.4569526550039882s: None
[2021-02-24 09:57:57,080: INFO/ForkPoolWorker-4] [=][33m收到邮件发送任务  发件人: [ak47__98k@163.com]  主机: [smtp.163.com:25]  目标: [['ak47__98k@163.com', 'yaoyq@lianlianpay.com']]  内容: [70][0m
[2021-02-24 09:57:57,126: INFO/MainProcess] Received task: task.mail_to[5b89b28c-c24b-47e6-ac4f-2efbeef5a02b]  
[2021-02-24 10:08:51,492: ERROR/ForkPoolWorker-2] Task task.mail_to[c7439ea7-0780-4801-9ef6-c376c1de57b5] raised unexpected: TimeoutError(110, 'Connection timed out')
Traceback (most recent call last):
  File "/home/runner/detector/venv/lib/python3.8/site-packages/celery/app/trace.py", line 405, in trace_task
    R = retval = fun(*args, **kwargs)
  File "/home/runner/detector/venv/lib/python3.8/site-packages/celery/app/trace.py", line 697, in __protected_call__
    return self.run(*args, **kwargs)
  File "/home/runner/detector/task.py", line 53, in mail_to
    client.send(to=targets, subject=subject, contents=content)
  File "/home/runner/detector/venv/lib/python3.8/site-packages/yagmail/sender.py", line 153, in send
    self.login()
  File "/home/runner/detector/venv/lib/python3.8/site-packages/yagmail/sender.py", line 206, in login
    self._login(self.credentials)
  File "/home/runner/detector/venv/lib/python3.8/site-packages/yagmail/sender.py", line 213, in _login
    self.smtp = self.connection(self.host, self.port, **self.kwargs)
  File "/usr/lib/python3.8/smtplib.py", line 253, in __init__
    (code, msg) = self.connect(host, port)
  File "/usr/lib/python3.8/smtplib.py", line 337, in connect
    self.sock = self._get_socket(host, port, self.timeout)
  File "/usr/lib/python3.8/smtplib.py", line 308, in _get_socket
    return socket.create_connection((host, port), timeout,
  File "/usr/lib/python3.8/socket.py", line 808, in create_connection
    raise err
  File "/usr/lib/python3.8/socket.py", line 796, in create_connection
    sock.connect(sa)
TimeoutError: [Errno 110] Connection timed out
[2021-02-24 10:08:51,500: INFO/ForkPoolWorker-2] [=][33m收到邮件发送任务  发件人: [ak47__98k@163.com]  主机: [smtp.163.com:25]  目标: [['ak47__98k@163.com', 'yaoyq@lianlianpay.com']]  内容: [70][0m
[2021-02-24 10:08:51,497: ERROR/ForkPoolWorker-4] Task task.mail_to[a6ea014a-a69d-4f09-9886-2687268a737f] raised unexpected: TimeoutError(110, 'Connection timed out')
Traceback (most recent call last):
  File "/home/runner/detector/venv/lib/python3.8/site-packages/celery/app/trace.py", line 405, in trace_task
    R = retval = fun(*args, **kwargs)
  File "/home/runner/detector/venv/lib/python3.8/site-packages/celery/app/trace.py", line 697, in __protected_call__
    return self.run(*args, **kwargs)
  File "/home/runner/detector/task.py", line 53, in mail_to
    client.send(to=targets, subject=subject, contents=content)
  File "/home/runner/detector/venv/lib/python3.8/site-packages/yagmail/sender.py", line 153, in send
    self.login()
  File "/home/runner/detector/venv/lib/python3.8/site-packages/yagmail/sender.py", line 206, in login
    self._login(self.credentials)
  File "/home/runner/detector/venv/lib/python3.8/site-packages/yagmail/sender.py", line 213, in _login
    self.smtp = self.connection(self.host, self.port, **self.kwargs)
  File "/usr/lib/python3.8/smtplib.py", line 253, in __init__
    (code, msg) = self.connect(host, port)
  File "/usr/lib/python3.8/smtplib.py", line 337, in connect
    self.sock = self._get_socket(host, port, self.timeout)
  File "/usr/lib/python3.8/smtplib.py", line 308, in _get_socket
    return socket.create_connection((host, port), timeout,
  File "/usr/lib/python3.8/socket.py", line 808, in create_connection
    raise err
  File "/usr/lib/python3.8/socket.py", line 796, in create_connection
    sock.connect(sa)
TimeoutError: [Errno 110] Connection timed out
[2021-02-24 10:08:51,496: ERROR/ForkPoolWorker-1] Task task.mail_to[a7614315-48f4-479a-b621-3758247b22a3] raised unexpected: TimeoutError(110, 'Connection timed out')
Traceback (most recent call last):
  File "/home/runner/detector/venv/lib/python3.8/site-packages/celery/app/trace.py", line 405, in trace_task
    R = retval = fun(*args, **kwargs)
  File "/home/runner/detector/venv/lib/python3.8/site-packages/celery/app/trace.py", line 697, in __protected_call__
    return self.run(*args, **kwargs)
  File "/home/runner/detector/task.py", line 53, in mail_to
    client.send(to=targets, subject=subject, contents=content)
  File "/home/runner/detector/venv/lib/python3.8/site-packages/yagmail/sender.py", line 153, in send
    self.login()
  File "/home/runner/detector/venv/lib/python3.8/site-packages/yagmail/sender.py", line 206, in login
    self._login(self.credentials)
  File "/home/runner/detector/venv/lib/python3.8/site-packages/yagmail/sender.py", line 213, in _login
    self.smtp = self.connection(self.host, self.port, **self.kwargs)
  File "/usr/lib/python3.8/smtplib.py", line 253, in __init__
    (code, msg) = self.connect(host, port)
  File "/usr/lib/python3.8/smtplib.py", line 337, in connect
    self.sock = self._get_socket(host, port, self.timeout)
  File "/usr/lib/python3.8/smtplib.py", line 308, in _get_socket
    return socket.create_connection((host, port), timeout,
  File "/usr/lib/python3.8/socket.py", line 808, in create_connection
    raise err
  File "/usr/lib/python3.8/socket.py", line 796, in create_connection
    sock.connect(sa)
TimeoutError: [Errno 110] Connection timed out
[2021-02-24 10:08:51,497: ERROR/ForkPoolWorker-3] Task task.mail_to[f6f8090b-36e3-416f-85af-5b290896f440] raised unexpected: TimeoutError(110, 'Connection timed out')
Traceback (most recent call last):
  File "/home/runner/detector/venv/lib/python3.8/site-packages/celery/app/trace.py", line 405, in trace_task
    R = retval = fun(*args, **kwargs)
  File "/home/runner/detector/venv/lib/python3.8/site-packages/celery/app/trace.py", line 697, in __protected_call__
    return self.run(*args, **kwargs)
  File "/home/runner/detector/task.py", line 53, in mail_to
    client.send(to=targets, subject=subject, contents=content)
  File "/home/runner/detector/venv/lib/python3.8/site-packages/yagmail/sender.py", line 153, in send
    self.login()
  File "/home/runner/detector/venv/lib/python3.8/site-packages/yagmail/sender.py", line 206, in login
    self._login(self.credentials)
  File "/home/runner/detector/venv/lib/python3.8/site-packages/yagmail/sender.py", line 213, in _login
    self.smtp = self.connection(self.host, self.port, **self.kwargs)
  File "/usr/lib/python3.8/smtplib.py", line 253, in __init__
    (code, msg) = self.connect(host, port)
  File "/usr/lib/python3.8/smtplib.py", line 337, in connect
    self.sock = self._get_socket(host, port, self.timeout)
  File "/usr/lib/python3.8/smtplib.py", line 308, in _get_socket
    return socket.create_connection((host, port), timeout,
  File "/usr/lib/python3.8/socket.py", line 808, in create_connection
    raise err
  File "/usr/lib/python3.8/socket.py", line 796, in create_connection
    sock.connect(sa)
TimeoutError: [Errno 110] Connection timed out
[2021-02-24 10:08:51,685: INFO/MainProcess] Received task: task.mail_to[c4ed24e0-ee1f-40ad-98ce-048567076de9]  
[2021-02-24 10:08:51,688: INFO/ForkPoolWorker-4] [=][33m收到邮件发送任务  发件人: [ak47__98k@163.com]  主机: [smtp.163.com:25]  目标: [['ak47__98k@163.com', 'yaoyq@lianlianpay.com']]  内容: [70][0m
[2021-02-24 10:08:51,728: INFO/MainProcess] Received task: task.mail_to[4b3951b0-b92f-4a15-8945-51d4bc1074e7]  
[2021-02-24 10:08:51,730: INFO/ForkPoolWorker-1] [=][33m收到邮件发送任务  发件人: [ak47__98k@163.com]  主机: [smtp.163.com:25]  目标: [['ak47__98k@163.com', 'yaoyq@lianlianpay.com']]  内容: [70][0m
[2021-02-24 10:08:51,769: INFO/MainProcess] Received task: task.mail_to[4f133e92-359f-4538-acc0-f4c30dcd7a43]  
[2021-02-24 10:08:51,772: INFO/ForkPoolWorker-3] [=][33m收到邮件发送任务  发件人: [ak47__98k@163.com]  主机: [smtp.163.com:25]  目标: [['ak47__98k@163.com', 'yaoyq@lianlianpay.com']]  内容: [70][0m
[2021-02-24 10:08:51,811: INFO/MainProcess] Received task: task.mail_to[bbc88d0c-04c2-4785-8ad8-0e02a4feadfa]  
 
 -------------- celery@5bf010944cea v5.0.5 (singularity)
--- ***** ----- 
-- ******* ---- Linux-5.4.0-1019-gcp-x86_64-with-glibc2.27 2021-02-25 05:38:09
- *** --- * --- 
- ** ---------- [config]
- ** ---------- .> app:         CVEMonitor:0x7f31d5ad9d30
- ** ---------- .> transport:   sqla+sqlite:///CVEMonitor_worker.db
- ** ---------- .> results:     disabled://
- *** --- * --- .> concurrency: 4 (prefork)
-- ******* ---- .> task events: OFF (enable -E to monitor tasks in this worker)
--- ***** ----- 
 -------------- [queues]
                .> celery           exchange=celery(direct) key=celery
                

[tasks]
  . task.feishu
  . task.mail_to

[2021-02-25 05:38:10,622: INFO/MainProcess] Connected to sqla+sqlite:///CVEMonitor_worker.db
[2021-02-25 05:38:10,830: INFO/MainProcess] celery@5bf010944cea ready.
[2021-02-25 05:38:11,020: INFO/MainProcess] Received task: task.mail_to[0972ecf6-2739-4350-90a6-6c7d31666b71]  
[2021-02-25 05:38:11,025: INFO/ForkPoolWorker-1] [=][33m收到邮件发送任务  发件人: [ak47__98k@163.com]  主机: [smtp.163.com:25]  目标: [['ak47__98k@163.com', 'wenpp@lianlianpay.com', 'yaoyq@lianlianpay.com']]  内容: [70][0m
[2021-02-25 05:38:11,218: INFO/MainProcess] Received task: task.mail_to[b611fb26-78a0-483c-a81a-26084b852631]  
[2021-02-25 05:38:11,222: INFO/ForkPoolWorker-3] [=][33m收到邮件发送任务  发件人: [ak47__98k@163.com]  主机: [smtp.163.com:25]  目标: [['ak47__98k@163.com', 'wenpp@lianlianpay.com', 'yaoyq@lianlianpay.com']]  内容: [70][0m
[2021-02-25 05:38:11,319: INFO/MainProcess] Received task: task.mail_to[8dc9921a-a089-48eb-8df5-f15e28d4adc1]  
[2021-02-25 05:38:11,322: INFO/ForkPoolWorker-4] [=][33m收到邮件发送任务  发件人: [ak47__98k@163.com]  主机: [smtp.163.com:25]  目标: [['ak47__98k@163.com', 'wenpp@lianlianpay.com', 'yaoyq@lianlianpay.com']]  内容: [70][0m
[2021-02-25 05:38:11,435: INFO/MainProcess] Received task: task.mail_to[ffcc5671-89a1-4ac0-a432-d4d257cf7492]  
[2021-02-25 05:38:11,440: INFO/ForkPoolWorker-2] [=][33m收到邮件发送任务  发件人: [ak47__98k@163.com]  主机: [smtp.163.com:25]  目标: [['ak47__98k@163.com', 'wenpp@lianlianpay.com', 'yaoyq@lianlianpay.com']]  内容: [70][0m
[2021-02-25 05:38:11,524: INFO/MainProcess] Received task: task.mail_to[551eb5ea-4f21-4cde-a87c-4e151e8ee6b6]  
 
 -------------- celery@3dffd420d079 v5.0.5 (singularity)
--- ***** ----- 
-- ******* ---- Linux-5.4.0-1019-gcp-x86_64-with-glibc2.27 2021-03-01 10:12:51
- *** --- * --- 
- ** ---------- [config]
- ** ---------- .> app:         CVEMonitor:0x7fdc2a08bd30
- ** ---------- .> transport:   sqla+sqlite:///CVEMonitor_worker.db
- ** ---------- .> results:     disabled://
- *** --- * --- .> concurrency: 4 (prefork)
-- ******* ---- .> task events: OFF (enable -E to monitor tasks in this worker)
--- ***** ----- 
 -------------- [queues]
                .> celery           exchange=celery(direct) key=celery
                

[tasks]
  . task.feishu
  . task.mail_to

[2021-03-01 10:12:56,684: INFO/MainProcess] Connected to sqla+sqlite:///CVEMonitor_worker.db
[2021-03-01 10:12:58,681: INFO/MainProcess] celery@3dffd420d079 ready.
[2021-03-01 10:12:59,380: INFO/MainProcess] Received task: task.mail_to[739d08cd-be5d-4daf-9f36-504695be73b3]  
[2021-03-01 10:12:59,556: INFO/ForkPoolWorker-1] [=][33m收到邮件发送任务  发件人: [ak47__98k@163.com]  主机: [smtp.163.com:25]  目标: [['ak47__98k@163.com', 'wenpp@lianlianpay.com', 'yaoyq@lianlianpay.com']]  内容: [70][0m
[2021-03-01 10:13:00,301: INFO/MainProcess] Received task: task.mail_to[cf7845e9-4b01-498d-9763-73b7cd77559a]  
[2021-03-01 10:13:00,436: INFO/ForkPoolWorker-2] [=][33m收到邮件发送任务  发件人: [ak47__98k@163.com]  主机: [smtp.163.com:25]  目标: [['ak47__98k@163.com', 'wenpp@lianlianpay.com', 'yaoyq@lianlianpay.com']]  内容: [70][0m
[2021-03-01 10:13:01,019: INFO/MainProcess] Received task: task.feishu[1bd0eeda-8abc-408f-bcab-75fee68e1458]  
[2021-03-01 10:13:02,400: INFO/MainProcess] Received task: task.mail_to[4f4fb679-23d7-4b0e-b75b-b2c2f60c092f]  
[2021-03-01 10:13:02,688: INFO/ForkPoolWorker-4] [=][33m收到邮件发送任务  发件人: [ak47__98k@163.com]  主机: [smtp.163.com:25]  目标: [['ak47__98k@163.com', 'wenpp@lianlianpay.com', 'yaoyq@lianlianpay.com']]  内容: [70][0m
[2021-03-01 10:13:03,486: INFO/MainProcess] Received task: task.feishu[bc097e12-ec8b-4e4b-a0c1-58d8c471b5ac]  
[2021-03-01 10:13:04,635: INFO/ForkPoolWorker-3] Task task.feishu[1bd0eeda-8abc-408f-bcab-75fee68e1458] succeeded in 3.435444771006587s: None
[2021-03-01 10:13:05,976: INFO/MainProcess] Received task: task.mail_to[9596a7e3-c42a-4ec2-acdc-2bb642a62675]  
[2021-03-01 10:13:06,814: INFO/ForkPoolWorker-3] Task task.feishu[bc097e12-ec8b-4e4b-a0c1-58d8c471b5ac] succeeded in 2.152923526999075s: None
[2021-03-01 10:13:06,946: INFO/ForkPoolWorker-3] [=][33m收到邮件发送任务  发件人: [ak47__98k@163.com]  主机: [smtp.163.com:25]  目标: [['ak47__98k@163.com', 'wenpp@lianlianpay.com', 'yaoyq@lianlianpay.com']]  内容: [70][0m
[2021-03-01 10:13:08,428: INFO/MainProcess] Received task: task.feishu[28f11964-8dd4-464b-a67b-32831d400b48]  
[2021-03-01 10:23:55,299: ERROR/ForkPoolWorker-1] Task task.mail_to[739d08cd-be5d-4daf-9f36-504695be73b3] raised unexpected: TimeoutError(110, 'Connection timed out')
Traceback (most recent call last):
  File "/home/runner/detector/venv/lib/python3.8/site-packages/celery/app/trace.py", line 405, in trace_task
    R = retval = fun(*args, **kwargs)
  File "/home/runner/detector/venv/lib/python3.8/site-packages/celery/app/trace.py", line 697, in __protected_call__
    return self.run(*args, **kwargs)
  File "/home/runner/detector/task.py", line 53, in mail_to
    client.send(to=targets, subject=subject, contents=content)
  File "/home/runner/detector/venv/lib/python3.8/site-packages/yagmail/sender.py", line 153, in send
    self.login()
  File "/home/runner/detector/venv/lib/python3.8/site-packages/yagmail/sender.py", line 206, in login
    self._login(self.credentials)
  File "/home/runner/detector/venv/lib/python3.8/site-packages/yagmail/sender.py", line 213, in _login
    self.smtp = self.connection(self.host, self.port, **self.kwargs)
  File "/usr/lib/python3.8/smtplib.py", line 253, in __init__
    (code, msg) = self.connect(host, port)
  File "/usr/lib/python3.8/smtplib.py", line 337, in connect
    self.sock = self._get_socket(host, port, self.timeout)
  File "/usr/lib/python3.8/smtplib.py", line 308, in _get_socket
    return socket.create_connection((host, port), timeout,
  File "/usr/lib/python3.8/socket.py", line 808, in create_connection
    raise err
  File "/usr/lib/python3.8/socket.py", line 796, in create_connection
    sock.connect(sa)
TimeoutError: [Errno 110] Connection timed out
[2021-03-01 10:23:55,624: ERROR/ForkPoolWorker-2] Task task.mail_to[cf7845e9-4b01-498d-9763-73b7cd77559a] raised unexpected: TimeoutError(110, 'Connection timed out')
Traceback (most recent call last):
  File "/home/runner/detector/venv/lib/python3.8/site-packages/celery/app/trace.py", line 405, in trace_task
    R = retval = fun(*args, **kwargs)
  File "/home/runner/detector/venv/lib/python3.8/site-packages/celery/app/trace.py", line 697, in __protected_call__
    return self.run(*args, **kwargs)
  File "/home/runner/detector/task.py", line 53, in mail_to
    client.send(to=targets, subject=subject, contents=content)
  File "/home/runner/detector/venv/lib/python3.8/site-packages/yagmail/sender.py", line 153, in send
    self.login()
  File "/home/runner/detector/venv/lib/python3.8/site-packages/yagmail/sender.py", line 206, in login
    self._login(self.credentials)
  File "/home/runner/detector/venv/lib/python3.8/site-packages/yagmail/sender.py", line 213, in _login
    self.smtp = self.connection(self.host, self.port, **self.kwargs)
  File "/usr/lib/python3.8/smtplib.py", line 253, in __init__
    (code, msg) = self.connect(host, port)
  File "/usr/lib/python3.8/smtplib.py", line 337, in connect
    self.sock = self._get_socket(host, port, self.timeout)
  File "/usr/lib/python3.8/smtplib.py", line 308, in _get_socket
    return socket.create_connection((host, port), timeout,
  File "/usr/lib/python3.8/socket.py", line 808, in create_connection
    raise err
  File "/usr/lib/python3.8/socket.py", line 796, in create_connection
    sock.connect(sa)
TimeoutError: [Errno 110] Connection timed out
[2021-03-01 10:23:56,839: INFO/MainProcess] Received task: task.mail_to[dc8177db-4561-480a-b9ee-d057112e41d7]  
[2021-03-01 10:23:56,915: ERROR/ForkPoolWorker-4] Task task.mail_to[4f4fb679-23d7-4b0e-b75b-b2c2f60c092f] raised unexpected: TimeoutError(110, 'Connection timed out')
Traceback (most recent call last):
  File "/home/runner/detector/venv/lib/python3.8/site-packages/celery/app/trace.py", line 405, in trace_task
    R = retval = fun(*args, **kwargs)
  File "/home/runner/detector/venv/lib/python3.8/site-packages/celery/app/trace.py", line 697, in __protected_call__
    return self.run(*args, **kwargs)
  File "/home/runner/detector/task.py", line 53, in mail_to
    client.send(to=targets, subject=subject, contents=content)
  File "/home/runner/detector/venv/lib/python3.8/site-packages/yagmail/sender.py", line 153, in send
    self.login()
  File "/home/runner/detector/venv/lib/python3.8/site-packages/yagmail/sender.py", line 206, in login
    self._login(self.credentials)
  File "/home/runner/detector/venv/lib/python3.8/site-packages/yagmail/sender.py", line 213, in _login
    self.smtp = self.connection(self.host, self.port, **self.kwargs)
  File "/usr/lib/python3.8/smtplib.py", line 253, in __init__
    (code, msg) = self.connect(host, port)
  File "/usr/lib/python3.8/smtplib.py", line 337, in connect
    self.sock = self._get_socket(host, port, self.timeout)
  File "/usr/lib/python3.8/smtplib.py", line 308, in _get_socket
    return socket.create_connection((host, port), timeout,
  File "/usr/lib/python3.8/socket.py", line 808, in create_connection
    raise err
  File "/usr/lib/python3.8/socket.py", line 796, in create_connection
    sock.connect(sa)
TimeoutError: [Errno 110] Connection timed out
[2021-03-01 10:23:57,079: INFO/ForkPoolWorker-2] [=][33m收到邮件发送任务  发件人: [ak47__98k@163.com]  主机: [smtp.163.com:25]  目标: [['ak47__98k@163.com', 'wenpp@lianlianpay.com', 'yaoyq@lianlianpay.com']]  内容: [157][0m
[2021-03-01 10:23:57,488: INFO/MainProcess] Received task: task.feishu[d365f3f9-b3b5-477e-bd81-93b77d0e87a1]  
[2021-03-01 10:23:58,028: INFO/MainProcess] Received task: task.mail_to[83f0f796-3e28-4271-85a1-a2c8c1443b1b]  
[2021-03-01 10:23:58,800: INFO/ForkPoolWorker-4] Task task.feishu[d365f3f9-b3b5-477e-bd81-93b77d0e87a1] succeeded in 1.2877536180021707s: None
[2021-03-01 10:23:58,839: INFO/ForkPoolWorker-4] [=][33m收到邮件发送任务  发件人: [ak47__98k@163.com]  主机: [smtp.163.com:25]  目标: [['ak47__98k@163.com', 'wenpp@lianlianpay.com', 'yaoyq@lianlianpay.com']]  内容: [157][0m
[2021-03-01 10:23:59,138: INFO/MainProcess] Received task: task.feishu[561bf0a4-d9df-4efb-8421-14b702b78b4d]  
[2021-03-01 10:24:00,367: INFO/ForkPoolWorker-1] Task task.feishu[28f11964-8dd4-464b-a67b-32831d400b48] succeeded in 4.626465771987569s: None
[2021-03-01 10:24:01,007: INFO/MainProcess] Received task: task.mail_to[279660ff-0fe9-4baf-90be-c13199224a20]  
[2021-03-01 10:24:02,963: ERROR/ForkPoolWorker-3] Task task.mail_to[9596a7e3-c42a-4ec2-acdc-2bb642a62675] raised unexpected: TimeoutError(110, 'Connection timed out')
Traceback (most recent call last):
  File "/home/runner/detector/venv/lib/python3.8/site-packages/celery/app/trace.py", line 405, in trace_task
    R = retval = fun(*args, **kwargs)
  File "/home/runner/detector/venv/lib/python3.8/site-packages/celery/app/trace.py", line 697, in __protected_call__
    return self.run(*args, **kwargs)
  File "/home/runner/detector/task.py", line 53, in mail_to
    client.send(to=targets, subject=subject, contents=content)
  File "/home/runner/detector/venv/lib/python3.8/site-packages/yagmail/sender.py", line 153, in send
    self.login()
  File "/home/runner/detector/venv/lib/python3.8/site-packages/yagmail/sender.py", line 206, in login
    self._login(self.credentials)
  File "/home/runner/detector/venv/lib/python3.8/site-packages/yagmail/sender.py", line 213, in _login
    self.smtp = self.connection(self.host, self.port, **self.kwargs)
  File "/usr/lib/python3.8/smtplib.py", line 253, in __init__
    (code, msg) = self.connect(host, port)
  File "/usr/lib/python3.8/smtplib.py", line 337, in connect
    self.sock = self._get_socket(host, port, self.timeout)
  File "/usr/lib/python3.8/smtplib.py", line 308, in _get_socket
    return socket.create_connection((host, port), timeout,
  File "/usr/lib/python3.8/socket.py", line 808, in create_connection
    raise err
  File "/usr/lib/python3.8/socket.py", line 796, in create_connection
    sock.connect(sa)
TimeoutError: [Errno 110] Connection timed out
[2021-03-01 10:24:03,630: INFO/ForkPoolWorker-1] Task task.feishu[561bf0a4-d9df-4efb-8421-14b702b78b4d] succeeded in 3.0717429619980976s: None
[2021-03-01 10:24:03,662: INFO/ForkPoolWorker-3] [=][33m收到邮件发送任务  发件人: [ak47__98k@163.com]  主机: [smtp.163.com:25]  目标: [['ak47__98k@163.com', 'wenpp@lianlianpay.com', 'yaoyq@lianlianpay.com']]  内容: [157][0m
[2021-03-01 10:24:04,986: INFO/MainProcess] Received task: task.feishu[fef7fe28-cdb8-4a80-97cf-3ad6ce76309b]  
[2021-03-01 10:24:06,087: INFO/MainProcess] Received task: task.mail_to[7f069e87-cf4f-450b-b6b6-10a2b75e3e61]  
[2021-03-01 10:24:06,738: INFO/ForkPoolWorker-1] Task task.feishu[fef7fe28-cdb8-4a80-97cf-3ad6ce76309b] succeeded in 1.6788121739955386s: None
[2021-03-01 10:24:06,809: INFO/ForkPoolWorker-1] [=][33m收到邮件发送任务  发件人: [ak47__98k@163.com]  主机: [smtp.163.com:25]  目标: [['ak47__98k@163.com', 'wenpp@lianlianpay.com', 'yaoyq@lianlianpay.com']]  内容: [157][0m
[2021-03-01 10:24:07,195: INFO/MainProcess] Received task: task.feishu[1f928e66-b4c2-42f2-8d34-53d18f720b9f]  
[2021-03-01 10:34:52,109: ERROR/ForkPoolWorker-2] Task task.mail_to[dc8177db-4561-480a-b9ee-d057112e41d7] raised unexpected: TimeoutError(110, 'Connection timed out')
Traceback (most recent call last):
  File "/home/runner/detector/venv/lib/python3.8/site-packages/celery/app/trace.py", line 405, in trace_task
    R = retval = fun(*args, **kwargs)
  File "/home/runner/detector/venv/lib/python3.8/site-packages/celery/app/trace.py", line 697, in __protected_call__
    return self.run(*args, **kwargs)
  File "/home/runner/detector/task.py", line 53, in mail_to
    client.send(to=targets, subject=subject, contents=content)
  File "/home/runner/detector/venv/lib/python3.8/site-packages/yagmail/sender.py", line 153, in send
    self.login()
  File "/home/runner/detector/venv/lib/python3.8/site-packages/yagmail/sender.py", line 206, in login
    self._login(self.credentials)
  File "/home/runner/detector/venv/lib/python3.8/site-packages/yagmail/sender.py", line 213, in _login
    self.smtp = self.connection(self.host, self.port, **self.kwargs)
  File "/usr/lib/python3.8/smtplib.py", line 253, in __init__
    (code, msg) = self.connect(host, port)
  File "/usr/lib/python3.8/smtplib.py", line 337, in connect
    self.sock = self._get_socket(host, port, self.timeout)
  File "/usr/lib/python3.8/smtplib.py", line 308, in _get_socket
    return socket.create_connection((host, port), timeout,
  File "/usr/lib/python3.8/socket.py", line 808, in create_connection
    raise err
  File "/usr/lib/python3.8/socket.py", line 796, in create_connection
    sock.connect(sa)
TimeoutError: [Errno 110] Connection timed out
[2021-03-01 10:34:52,888: INFO/MainProcess] Received task: task.mail_to[aa5e8383-ac17-44f7-bd1f-7fdacdf6956d]  
[2021-03-01 10:34:54,136: INFO/ForkPoolWorker-2] Task task.feishu[1f928e66-b4c2-42f2-8d34-53d18f720b9f] succeeded in 1.9910789240093436s: None
[2021-03-01 10:34:54,159: ERROR/ForkPoolWorker-4] Task task.mail_to[83f0f796-3e28-4271-85a1-a2c8c1443b1b] raised unexpected: TimeoutError(110, 'Connection timed out')
Traceback (most recent call last):
  File "/home/runner/detector/venv/lib/python3.8/site-packages/celery/app/trace.py", line 405, in trace_task
    R = retval = fun(*args, **kwargs)
  File "/home/runner/detector/venv/lib/python3.8/site-packages/celery/app/trace.py", line 697, in __protected_call__
    return self.run(*args, **kwargs)
  File "/home/runner/detector/task.py", line 53, in mail_to
    client.send(to=targets, subject=subject, contents=content)
  File "/home/runner/detector/venv/lib/python3.8/site-packages/yagmail/sender.py", line 153, in send
    self.login()
  File "/home/runner/detector/venv/lib/python3.8/site-packages/yagmail/sender.py", line 206, in login
    self._login(self.credentials)
  File "/home/runner/detector/venv/lib/python3.8/site-packages/yagmail/sender.py", line 213, in _login
    self.smtp = self.connection(self.host, self.port, **self.kwargs)
  File "/usr/lib/python3.8/smtplib.py", line 253, in __init__
    (code, msg) = self.connect(host, port)
  File "/usr/lib/python3.8/smtplib.py", line 337, in connect
    self.sock = self._get_socket(host, port, self.timeout)
  File "/usr/lib/python3.8/smtplib.py", line 308, in _get_socket
    return socket.create_connection((host, port), timeout,
  File "/usr/lib/python3.8/socket.py", line 808, in create_connection
    raise err
  File "/usr/lib/python3.8/socket.py", line 796, in create_connection
    sock.connect(sa)
TimeoutError: [Errno 110] Connection timed out
[2021-03-01 10:34:54,226: INFO/ForkPoolWorker-2] [=][33m收到邮件发送任务  发件人: [ak47__98k@163.com]  主机: [smtp.163.com:25]  目标: [['ak47__98k@163.com', 'wenpp@lianlianpay.com', 'yaoyq@lianlianpay.com']]  内容: [157][0m
[2021-03-01 10:34:55,025: INFO/MainProcess] Received task: task.feishu[ff18ed2d-3d58-4e05-b06a-e5d318189e62]  
[2021-03-01 10:34:56,716: INFO/ForkPoolWorker-4] Task task.feishu[ff18ed2d-3d58-4e05-b06a-e5d318189e62] succeeded in 1.6525608209922211s: None
[2021-03-01 10:34:57,862: INFO/MainProcess] Received task: task.mail_to[33f1af5a-6696-46f4-b232-c0e36dc831aa]  
[2021-03-01 10:34:57,879: INFO/ForkPoolWorker-4] [=][33m收到邮件发送任务  发件人: [ak47__98k@163.com]  主机: [smtp.163.com:25]  目标: [['ak47__98k@163.com', 'wenpp@lianlianpay.com', 'yaoyq@lianlianpay.com']]  内容: [157][0m
[2021-03-01 10:34:58,287: ERROR/ForkPoolWorker-3] Task task.mail_to[279660ff-0fe9-4baf-90be-c13199224a20] raised unexpected: TimeoutError(110, 'Connection timed out')
Traceback (most recent call last):
  File "/home/runner/detector/venv/lib/python3.8/site-packages/celery/app/trace.py", line 405, in trace_task
    R = retval = fun(*args, **kwargs)
  File "/home/runner/detector/venv/lib/python3.8/site-packages/celery/app/trace.py", line 697, in __protected_call__
    return self.run(*args, **kwargs)
  File "/home/runner/detector/task.py", line 53, in mail_to
    client.send(to=targets, subject=subject, contents=content)
  File "/home/runner/detector/venv/lib/python3.8/site-packages/yagmail/sender.py", line 153, in send
    self.login()
  File "/home/runner/detector/venv/lib/python3.8/site-packages/yagmail/sender.py", line 206, in login
    self._login(self.credentials)
  File "/home/runner/detector/venv/lib/python3.8/site-packages/yagmail/sender.py", line 213, in _login
    self.smtp = self.connection(self.host, self.port, **self.kwargs)
  File "/usr/lib/python3.8/smtplib.py", line 253, in __init__
    (code, msg) = self.connect(host, port)
  File "/usr/lib/python3.8/smtplib.py", line 337, in connect
    self.sock = self._get_socket(host, port, self.timeout)
  File "/usr/lib/python3.8/smtplib.py", line 308, in _get_socket
    return socket.create_connection((host, port), timeout,
  File "/usr/lib/python3.8/socket.py", line 808, in create_connection
    raise err
  File "/usr/lib/python3.8/socket.py", line 796, in create_connection
    sock.connect(sa)
TimeoutError: [Errno 110] Connection timed out
[2021-03-01 10:34:59,995: INFO/MainProcess] Received task: task.feishu[64e45eb0-fb3f-4f57-ab6b-456f3590fd06]  
[2021-03-01 10:35:00,832: INFO/MainProcess] Received task: task.mail_to[6273d7fe-fd1a-4f76-b727-37f43c47c6b1]  
[2021-03-01 10:35:02,213: INFO/ForkPoolWorker-3] Task task.feishu[64e45eb0-fb3f-4f57-ab6b-456f3590fd06] succeeded in 2.156341682988568s: None
[2021-03-01 10:35:02,298: INFO/ForkPoolWorker-3] [=][33m收到邮件发送任务  发件人: [ak47__98k@163.com]  主机: [smtp.163.com:25]  目标: [['ak47__98k@163.com', 'wenpp@lianlianpay.com', 'yaoyq@lianlianpay.com']]  内容: [157][0m
[2021-03-01 10:35:02,344: ERROR/ForkPoolWorker-1] Task task.mail_to[7f069e87-cf4f-450b-b6b6-10a2b75e3e61] raised unexpected: TimeoutError(110, 'Connection timed out')
Traceback (most recent call last):
  File "/home/runner/detector/venv/lib/python3.8/site-packages/celery/app/trace.py", line 405, in trace_task
    R = retval = fun(*args, **kwargs)
  File "/home/runner/detector/venv/lib/python3.8/site-packages/celery/app/trace.py", line 697, in __protected_call__
    return self.run(*args, **kwargs)
  File "/home/runner/detector/task.py", line 53, in mail_to
    client.send(to=targets, subject=subject, contents=content)
  File "/home/runner/detector/venv/lib/python3.8/site-packages/yagmail/sender.py", line 153, in send
    self.login()
  File "/home/runner/detector/venv/lib/python3.8/site-packages/yagmail/sender.py", line 206, in login
    self._login(self.credentials)
  File "/home/runner/detector/venv/lib/python3.8/site-packages/yagmail/sender.py", line 213, in _login
    self.smtp = self.connection(self.host, self.port, **self.kwargs)
  File "/usr/lib/python3.8/smtplib.py", line 253, in __init__
    (code, msg) = self.connect(host, port)
  File "/usr/lib/python3.8/smtplib.py", line 337, in connect
    self.sock = self._get_socket(host, port, self.timeout)
  File "/usr/lib/python3.8/smtplib.py", line 308, in _get_socket
    return socket.create_connection((host, port), timeout,
  File "/usr/lib/python3.8/socket.py", line 808, in create_connection
    raise err
  File "/usr/lib/python3.8/socket.py", line 796, in create_connection
    sock.connect(sa)
TimeoutError: [Errno 110] Connection timed out
[2021-03-01 10:35:03,358: INFO/MainProcess] Received task: task.feishu[218ba970-b561-4b31-82cc-0d24c2ac22a8]  
[2021-03-01 10:35:05,957: INFO/ForkPoolWorker-1] Task task.feishu[218ba970-b561-4b31-82cc-0d24c2ac22a8] succeeded in 2.39244482399954s: None
[2021-03-01 10:35:06,512: INFO/MainProcess] Received task: task.mail_to[24b5a952-cf25-406f-a92a-76d73817b6e6]  
[2021-03-01 10:35:06,516: INFO/ForkPoolWorker-1] [=][33m收到邮件发送任务  发件人: [ak47__98k@163.com]  主机: [smtp.163.com:25]  目标: [['ak47__98k@163.com', 'wenpp@lianlianpay.com', 'yaoyq@lianlianpay.com']]  内容: [157][0m
[2021-03-01 10:35:06,666: INFO/MainProcess] Received task: task.feishu[e8178e6e-38a1-47d5-8c6b-df29d149e423]  
